<?xml version="1.0"?>
<sdf version='1.7'>
  <model name='panda'>
    <joint name='panda_link0_to_world' type='fixed'>
      <pose relative_to='__model__'>0 0 0 0 -0 0</pose>
      <parent>world</parent>
      <child>panda_link0</child>
    </joint>
    <link name='panda_link0'>
      <pose relative_to='panda_link0_to_world'>0 0 0 0 -0 0</pose>
      <inertial>
        <pose>-0.025566 -2.9e-05 0.057332 0 -0 0</pose>
        <mass>2.81427</mass>
        <inertia>
          <ixx>0.00753906</ixx>
          <ixy>-1.50531e-05</ixy>
          <ixz>-0.00121443</ixz>
          <iyy>0.010508</iyy>
          <iyz>1.04348e-05</iyz>
          <izz>0.00986493</izz>
        </inertia>
      </inertial>
      <collision name='panda_link0_collision_collision'>
        <pose>0 0 0 0 -0 0</pose>
        <geometry>
          <mesh>
            <scale>1 1 1</scale>
            <uri>model://panda/meshes/collision/link0.stl</uri>
          </mesh>
        </geometry>
        <surface>
          <contact>
            <ode/>
          </contact>
          <friction>
            <ode>
              <mu>1.05</mu>
              <mu2>1.05</mu2>
            </ode>
          </friction>
        </surface>
      </collision>
      <visual name='panda_link0_visual_visual'>
        <pose>0 0 0 0 -0 0</pose>
        <geometry>
          <mesh>
            <scale>1 1 1</scale>
            <uri>model://panda/meshes/visual/link0.dae</uri>
          </mesh>
        </geometry>
        <material>
          <script>
            <name>Gazebo/DarkGrey</name>
            <uri>file://media/materials/scripts/gazebo.material</uri>
          </script>
        </material>
      </visual>
      <gravity>1</gravity>
      <velocity_decay/>
    </link>
    <joint name='panda_joint1' type='revolute'>
      <pose relative_to='panda_link0'>0 0 0.333 0 -0 0</pose>
      <parent>panda_link0</parent>
      <child>panda_link1</child>
      <axis>
        <xyz>0 0 1</xyz>
        <limit>
          <lower>-2.89725</lower>
          <upper>2.89725</upper>
          <effort>87</effort>
          <velocity>2.61799</velocity>
        </limit>
        <dynamics>
          <damping>21.75</damping>
          <friction>3.48</friction>
          <spring_reference>0</spring_reference>
          <spring_stiffness>0</spring_stiffness>
        </dynamics>
      </axis>
    </joint>
    <link name='panda_link1'>
      <pose relative_to='panda_joint1'>0 0 0 0 -0 0</pose>
      <inertial>
        <pose>-0 -0.032496 -0.067582 0 -0 0</pose>
        <mass>2.64332</mass>
        <inertia>
          <ixx>0.0174051</ixx>
          <ixy>-8.68799e-09</ixy>
          <ixz>-1.62778e-08</ixz>
          <iyy>0.0153521</iyy>
          <iyz>0.00451086</iyz>
          <izz>0.00598789</izz>
        </inertia>
      </inertial>
      <collision name='panda_link1_collision_collision'>
        <pose>0 0 0 0 -0 0</pose>
        <geometry>
          <mesh>
            <scale>1 1 1</scale>
            <uri>model://panda/meshes/collision/link1.stl</uri>
          </mesh>
        </geometry>
        <surface>
          <contact>
            <ode/>
          </contact>
          <friction>
            <ode>
              <mu>1.05</mu>
              <mu2>1.05</mu2>
            </ode>
          </friction>
        </surface>
      </collision>
      <visual name='panda_link1_visual_visual'>
        <pose>0 0 0 0 -0 0</pose>
        <geometry>
          <mesh>
            <scale>1 1 1</scale>
            <uri>model://panda/meshes/visual/link1.dae</uri>
          </mesh>
        </geometry>
        <material>
          <script>
            <name>Gazebo/Orange</name>
            <uri>file://media/materials/scripts/gazebo.material</uri>
          </script>
        </material>
      </visual>
      <gravity>1</gravity>
      <velocity_decay/>
    </link>
    <joint name='panda_joint2' type='revolute'>
      <pose relative_to='panda_link1'>0 0 0 -1.5708 0 0</pose>
      <parent>panda_link1</parent>
      <child>panda_link2</child>
      <axis>
        <xyz>0 0 1</xyz>
        <limit>
          <lower>-1.76278</lower>
          <upper>1.76278</upper>
          <effort>87</effort>
          <velocity>2.61799</velocity>
        </limit>
        <dynamics>
          <damping>21.75</damping>
          <friction>3.48</friction>
          <spring_reference>0</spring_reference>
          <spring_stiffness>0</spring_stiffness>
        </dynamics>
      </axis>
    </joint>
    <link name='panda_link2'>
      <pose relative_to='panda_joint2'>0 0 0 0 -0 0</pose>
      <inertial>
        <pose>0 -0.06861 0.032229 0 -0 0</pose>
        <mass>2.66528</mass>
        <inertia>
          <ixx>0.0177869</ixx>
          <ixy>8.70636e-08</ixy>
          <ixz>3.75207e-08</ixz>
          <iyy>0.00604413</iyy>
          <iyz>-0.00459949</iyz>
          <izz>0.015711</izz>
        </inertia>
      </inertial>
      <collision name='panda_link2_collision_collision'>
        <pose>0 0 0 0 -0 0</pose>
        <geometry>
          <mesh>
            <scale>1 1 1</scale>
            <uri>model://panda/meshes/collision/link2.stl</uri>
          </mesh>
        </geometry>
        <surface>
          <contact>
            <ode/>
          </contact>
          <friction>
            <ode>
              <mu>1.05</mu>
              <mu2>1.05</mu2>
            </ode>
          </friction>
        </surface>
      </collision>
      <visual name='panda_link2_visual_visual'>
        <pose>0 0 0 0 -0 0</pose>
        <geometry>
          <mesh>
            <scale>1 1 1</scale>
            <uri>model://panda/meshes/visual/link2.dae</uri>
          </mesh>
        </geometry>
        <material>
          <script>
            <name>Gazebo/Orange</name>
            <uri>file://media/materials/scripts/gazebo.material</uri>
          </script>
        </material>
      </visual>
      <gravity>1</gravity>
      <velocity_decay/>
    </link>
    <joint name='panda_joint3' type='revolute'>
      <pose relative_to='panda_link2'>0 -0.316 0 1.5708 -0 0</pose>
      <parent>panda_link2</parent>
      <child>panda_link3</child>
      <axis>
        <xyz>0 0 1</xyz>
        <limit>
          <lower>-2.89725</lower>
          <upper>2.89725</upper>
          <effort>87</effort>
          <velocity>2.61799</velocity>
        </limit>
        <dynamics>
          <damping>21.75</damping>
          <friction>3.48</friction>
          <spring_reference>0</spring_reference>
          <spring_stiffness>0</spring_stiffness>
        </dynamics>
      </axis>
    </joint>
    <link name='panda_link3'>
      <pose relative_to='panda_joint3'>0 0 0 0 -0 0</pose>
      <inertial>
        <pose>0.046989 0.031637 -0.031704 0 -0 0</pose>
        <mass>2.32937</mass>
        <inertia>
          <ixx>0.00754968</ixx>
          <ixy>-0.00243205</ixy>
          <ixz>-0.00325082</ixz>
          <iyy>0.00968068</iyy>
          <iyz>-0.00213163</iyz>
          <izz>0.00794456</izz>
        </inertia>
      </inertial>
      <collision name='panda_link3_collision_collision'>
        <pose>0 0 0 0 -0 0</pose>
        <geometry>
          <mesh>
            <scale>1 1 1</scale>
            <uri>model://panda/meshes/collision/link3.stl</uri>
          </mesh>
        </geometry>
        <surface>
          <contact>
            <ode/>
          </contact>
          <friction>
            <ode>
              <mu>1.05</mu>
              <mu2>1.05</mu2>
            </ode>
          </friction>
        </surface>
      </collision>
      <visual name='panda_link3_visual_visual'>
        <pose>0 0 0 0 -0 0</pose>
        <geometry>
          <mesh>
            <scale>1 1 1</scale>
            <uri>model://panda/meshes/visual/link3.dae</uri>
          </mesh>
        </geometry>
        <material>
          <script>
            <name>Gazebo/Orange</name>
            <uri>file://media/materials/scripts/gazebo.material</uri>
          </script>
        </material>
      </visual>
      <gravity>1</gravity>
      <velocity_decay/>
    </link>
    <joint name='panda_joint4' type='revolute'>
      <pose relative_to='panda_link3'>0.0825 0 0 1.5708 -0 0</pose>
      <parent>panda_link3</parent>
      <child>panda_link4</child>
      <axis>
        <xyz>0 0 1</xyz>
        <limit>
          <lower>-3.07178</lower>
          <upper>-0.0698132</upper>
          <effort>87</effort>
          <velocity>2.61799</velocity>
        </limit>
        <dynamics>
          <damping>21.75</damping>
          <friction>3.48</friction>
          <spring_reference>0</spring_reference>
          <spring_stiffness>0</spring_stiffness>
        </dynamics>
      </axis>
    </joint>
    <link name='panda_link4'>
      <pose relative_to='panda_joint4'>0 0 0 0 -0 0</pose>
      <inertial>
        <pose>-0.036051 0.033707 0.031902 0 -0 0</pose>
        <mass>2.31048</mass>
        <inertia>
          <ixx>0.00776457</ixx>
          <ixy>0.00337148</ixy>
          <ixz>-0.00234362</ixz>
          <iyy>0.00801578</iyy>
          <iyz>0.00229175</iyz>
          <izz>0.00995588</izz>
        </inertia>
      </inertial>
      <collision name='panda_link4_collision_collision'>
        <pose>0 0 0 0 -0 0</pose>
        <geometry>
          <mesh>
            <scale>1 1 1</scale>
            <uri>model://panda/meshes/collision/link4.stl</uri>
          </mesh>
        </geometry>
        <surface>
          <contact>
            <ode/>
          </contact>
          <friction>
            <ode>
              <mu>1.05</mu>
              <mu2>1.05</mu2>
            </ode>
          </friction>
        </surface>
      </collision>
      <visual name='panda_link4_visual_visual'>
        <pose>0 0 0 0 -0 0</pose>
        <geometry>
          <mesh>
            <scale>1 1 1</scale>
            <uri>model://panda/meshes/visual/link4.dae</uri>
          </mesh>
        </geometry>
        <material>
          <script>
            <name>Gazebo/Orange</name>
            <uri>file://media/materials/scripts/gazebo.material</uri>
          </script>
        </material>
      </visual>
      <gravity>1</gravity>
      <velocity_decay/>
    </link>
    <joint name='panda_joint5' type='revolute'>
      <pose relative_to='panda_link4'>-0.0825 0.384 0 -1.5708 0 0</pose>
      <parent>panda_link4</parent>
      <child>panda_link5</child>
      <axis>
        <xyz>0 0 1</xyz>
        <limit>
          <lower>-2.89725</lower>
          <upper>2.89725</upper>
          <effort>12</effort>
          <velocity>3.14159</velocity>
        </limit>
        <dynamics>
          <damping>3</damping>
          <friction>0.48</friction>
          <spring_reference>0</spring_reference>
          <spring_stiffness>0</spring_stiffness>
        </dynamics>
      </axis>
    </joint>
    <link name='panda_link5'>
      <pose relative_to='panda_joint5'>0 0 0 0 -0 0</pose>
      <inertial>
        <pose>-6e-06 0.061043 -0.104176 0 -0 0</pose>
        <mass>2.62264</mass>
        <inertia>
          <ixx>0.0290705</ixx>
          <ixy>6.20874e-07</ixy>
          <ixz>-1.00592e-05</ixz>
          <iyy>0.0276385</iyy>
          <iyz>-0.00742431</iyz>
          <izz>0.00425111</izz>
        </inertia>
      </inertial>
      <collision name='panda_link5_collision_collision'>
        <pose>0 0 0 0 -0 0</pose>
        <geometry>
          <mesh>
            <scale>1 1 1</scale>
            <uri>model://panda/meshes/collision/link5.stl</uri>
          </mesh>
        </geometry>
        <surface>
          <contact>
            <ode/>
          </contact>
          <friction>
            <ode>
              <mu>1.05</mu>
              <mu2>1.05</mu2>
            </ode>
          </friction>
        </surface>
      </collision>
      <visual name='panda_link5_visual_visual'>
        <pose>0 0 0 0 -0 0</pose>
        <geometry>
          <mesh>
            <scale>1 1 1</scale>
            <uri>model://panda/meshes/visual/link5.dae</uri>
          </mesh>
        </geometry>
        <material>
          <script>
            <name>Gazebo/Orange</name>
            <uri>file://media/materials/scripts/gazebo.material</uri>
          </script>
        </material>
      </visual>
      <gravity>1</gravity>
      <velocity_decay/>
    </link>
    <joint name='panda_joint6' type='revolute'>
      <pose relative_to='panda_link5'>0 0 0 1.5708 -0 0</pose>
      <parent>panda_link5</parent>
      <child>panda_link6</child>
      <axis>
        <xyz>0 0 1</xyz>
        <limit>
          <lower>-0.0174533</lower>
          <upper>3.75246</upper>
          <effort>12</effort>
          <velocity>3.14159</velocity>
        </limit>
        <dynamics>
          <damping>3</damping>
          <friction>0.48</friction>
          <spring_reference>0</spring_reference>
          <spring_stiffness>0</spring_stiffness>
        </dynamics>
      </axis>
    </joint>
    <link name='panda_link6'>
      <pose relative_to='panda_joint6'>0 0 0 0 -0 0</pose>
      <inertial>
        <pose>0 0 0 0 -0 0</pose>
        <mass>1.50258</mass>
        <inertia>
          <ixx>0.00294056</ixx>
          <ixy>-0.000423911</ixy>
          <ixz>0.000610008</ixz>
          <iyy>0.00392105</iyy>
          <iyz>0.000126475</iyz>
          <izz>0.00541156</izz>
        </inertia>
      </inertial>
      <collision name='panda_link6_collision_collision'>
        <pose>0 0 0 0 -0 0</pose>
        <geometry>
          <mesh>
            <scale>1 1 1</scale>
            <uri>model://panda/meshes/collision/link6.stl</uri>
          </mesh>
        </geometry>
        <surface>
          <contact>
            <ode/>
          </contact>
          <friction>
            <ode>
              <mu>1.05</mu>
              <mu2>1.05</mu2>
            </ode>
          </friction>
        </surface>
      </collision>
      <visual name='panda_link6_visual_visual'>
        <pose>0 0 0 0 -0 0</pose>
        <geometry>
          <mesh>
            <scale>1 1 1</scale>
            <uri>model://panda/meshes/visual/link6.dae</uri>
          </mesh>
        </geometry>
        <material>
          <script>
            <name>Gazebo/Orange</name>
            <uri>file://media/materials/scripts/gazebo.material</uri>
          </script>
        </material>
      </visual>
      <gravity>1</gravity>
      <velocity_decay/>
    </link>
    <joint name='panda_joint7' type='revolute'>
      <pose relative_to='panda_link6'>0.088 0 0 1.5708 -0 0</pose>
      <parent>panda_link6</parent>
      <child>panda_link7</child>
      <axis>
        <xyz>0 0 1</xyz>
        <limit>
          <lower>-2.89725</lower>
          <upper>2.89725</upper>
          <effort>12</effort>
          <velocity>3.14159</velocity>
        </limit>
        <dynamics>
          <damping>3</damping>
          <friction>0.48</friction>
          <spring_reference>0</spring_reference>
          <spring_stiffness>0</spring_stiffness>
        </dynamics>
      </axis>
    </joint>
    <link name='panda_link7'>
      <pose relative_to='panda_joint7'>0 0 0 0 -0 0</pose>
      <inertial>
        <pose>0.008875 0.008741 0.079761 0 -0 0</pose>
        <mass>0.664374</mass>
        <inertia>
          <ixx>0.00171562</ixx>
          <ixy>-0.000359114</ixy>
          <ixz>0.00011498</ixz>
          <iyy>0.00171515</iyy>
          <iyz>-1.56392e-05</iyz>
          <izz>0.00121125</izz>
        </inertia>
      </inertial>
      <collision name='panda_link7_collision_collision'>
        <pose>0 0 0 0 -0 0</pose>
        <geometry>
          <mesh>
            <scale>1 1 1</scale>
            <uri>model://panda/meshes/collision/link7.stl</uri>
          </mesh>
        </geometry>
        <surface>
          <contact>
            <ode/>
          </contact>
          <friction>
            <ode>
              <mu>1.05</mu>
              <mu2>1.05</mu2>
            </ode>
          </friction>
        </surface>
      </collision>
      <collision name='panda_link7_fixed_joint_lump__panda_hand_collision_collision_1'>
        <pose>0 0 0.107 0 0 -0.785398</pose>
        <geometry>
          <mesh>
            <scale>1 1 1</scale>
            <uri>model://panda/meshes/collision/hand.stl</uri>
          </mesh>
        </geometry>
        <surface>
          <contact>
            <ode/>
          </contact>
          <friction>
            <ode>
              <mu>1.05</mu>
              <mu2>1.05</mu2>
            </ode>
          </friction>
        </surface>
      </collision>
      <visual name='panda_link7_visual_visual'>
        <pose>0 0 0 0 -0 0</pose>
        <geometry>
          <mesh>
            <scale>1 1 1</scale>
            <uri>model://panda/meshes/visual/link7.dae</uri>
          </mesh>
        </geometry>
        <material>
          <script>
            <name>Gazebo/Orange</name>
            <uri>file://media/materials/scripts/gazebo.material</uri>
          </script>
        </material>
      </visual>
      <visual name='panda_link7_fixed_joint_lump__panda_hand_visual_visual_1'>
        <pose>0 0 0.107 0 0 -0.785398</pose>
        <geometry>
          <mesh>
            <scale>1 1 1</scale>
            <uri>model://panda/meshes/visual/hand.dae</uri>
          </mesh>
        </geometry>
        <material>
          <script>
            <name>Gazebo/Grey</name>
            <uri>file://media/materials/scripts/gazebo.material</uri>
          </script>
        </material>
      </visual>
      <velocity_decay/>
      <gravity>1</gravity>
      <velocity_decay/>
    </link>
    <joint name='panda_finger_joint1' type='prismatic'>
      <pose relative_to='panda_link7'>0 0 0.1654 0 0 -0.785398</pose>
      <parent>panda_link7</parent>
      <child>panda_leftfinger</child>
      <axis>
        <xyz>0 1 0</xyz>
        <limit>
          <lower>0</lower>
          <upper>0.04</upper>
          <effort>20</effort>
          <velocity>0.2</velocity>
        </limit>
        <dynamics>
          <damping>10</damping>
          <friction>0.5</friction>
          <spring_reference>0</spring_reference>
          <spring_stiffness>0</spring_stiffness>
        </dynamics>
      </axis>
    </joint>
    <link name='panda_leftfinger'>
      <pose relative_to='panda_finger_joint1'>0 0 0 0 -0 0</pose>
      <inertial>
        <pose>-6e-06 0.002278 -0.027712 0 -0 0</pose>
        <mass>0.223845</mass>
        <inertia>
          <ixx>6.74804e-05</ixx>
          <ixy>-4.10274e-09</ixy>
          <ixz>1.86937e-08</ixz>
          <iyy>6.62719e-05</iyy>
          <iyz>1.19675e-05</iyz>
          <izz>1.5504e-05</izz>
        </inertia>
      </inertial>
      <collision name='panda_leftfinger_collision_collision'>
        <pose>0 0 0 0 -0 0</pose>
        <geometry>
          <mesh>
            <scale>1 1 1</scale>
            <uri>model://panda/meshes/collision/finger.stl</uri>
          </mesh>
        </geometry>
        <surface>
          <contact>
            <ode/>
          </contact>
          <friction>
            <ode>
              <mu>1.05</mu>
              <mu2>1.05</mu2>
            </ode>
          </friction>
        </surface>
      </collision>
      <visual name='panda_leftfinger_visual_visual'>
        <pose>0 0 0 0 -0 0</pose>
        <geometry>
          <mesh>
            <scale>1 1 1</scale>
            <uri>model://panda/meshes/visual/finger.dae</uri>
          </mesh>
        </geometry>
        <material>
          <script>
            <name>Gazebo/DarkGrey</name>
            <uri>file://media/materials/scripts/gazebo.material</uri>
          </script>
        </material>
      </visual>
      <gravity>1</gravity>
      <velocity_decay/>
    </link>
    <joint name='panda_finger_joint2' type='prismatic'>
      <pose relative_to='panda_link7'>0 0 0.1654 0 0 -0.785398</pose>
      <parent>panda_link7</parent>
      <child>panda_rightfinger</child>
      <axis>
        <xyz>0 -1 0</xyz>
        <limit>
          <lower>0</lower>
          <upper>0.04</upper>
          <effort>20</effort>
          <velocity>0.2</velocity>
        </limit>
        <dynamics>
          <damping>10</damping>
          <friction>0.5</friction>
          <spring_reference>0</spring_reference>
          <spring_stiffness>0</spring_stiffness>
        </dynamics>
      </axis>
    </joint>
    <link name='panda_rightfinger'>
      <pose relative_to='panda_finger_joint2'>0 0 0 0 -0 0</pose>
      <inertial>
        <pose>-6e-06 0.002278 -0.027712 0 -0 3.14159</pose>
        <mass>0.223845</mass>
        <inertia>
          <ixx>6.74804e-05</ixx>
          <ixy>-4.10274e-09</ixy>
          <ixz>1.86937e-08</ixz>
          <iyy>6.62719e-05</iyy>
          <iyz>1.19675e-05</iyz>
          <izz>1.5504e-05</izz>
        </inertia>
      </inertial>
      <collision name='panda_rightfinger_collision_collision'>
        <pose>0 0 0 0 -0 3.14159</pose>
        <geometry>
          <mesh>
            <scale>1 1 1</scale>
            <uri>model://panda/meshes/collision/finger.stl</uri>
          </mesh>
        </geometry>
        <surface>
          <contact>
            <ode/>
          </contact>
          <friction>
            <ode>
              <mu>1.05</mu>
              <mu2>1.05</mu2>
            </ode>
          </friction>
        </surface>
      </collision>
      <visual name='panda_rightfinger_visual_visual'>
        <pose>0 0 0 0 -0 3.14159</pose>
        <geometry>
          <mesh>
            <scale>1 1 1</scale>
            <uri>model://panda/meshes/visual/finger.dae</uri>
          </mesh>
        </geometry>
        <material>
          <script>
            <name>Gazebo/DarkGrey</name>
            <uri>file://media/materials/scripts/gazebo.material</uri>
          </script>
        </material>
      </visual>
      <gravity>1</gravity>
      <velocity_decay/>
    </link>
  </model>
</sdf>
