<?xml version="1.0"?>
<robot name="panda" xmlns:xacro="http://www.ros.org/wiki/xacro">

    <xacro:arg name="gazebo" default="true" />

    <link name="world" />
    
    <!-- Fix To World -->
    <joint name="panda_link0_to_world" type="fixed">
        <parent link="world" />
        <child link="panda_link0" />
    </joint>

    <!-- Arm Links -->
    <link name="panda_link0">
        <visual name="panda_link0_visual">
            <geometry>
                <mesh filename="package://robot_description/meshes/visual/link0.dae" />
            </geometry>
        </visual>
        <collision name="panda_link0_collision">
            <geometry>
                <mesh filename="package://robot_description/meshes/collision/link0.stl" />
            </geometry>
        </collision>
        <xacro:if value="$(arg gazebo)">
            <inertial>
                <origin xyz="-0.025566 -2.87883e-05 0.057332" rpy="0 0 0" />
                <mass value="2.814271300104062" />
                <inertia
                    ixx="0.0075390636364814695"
                    iyy="0.010508017427382959"
                    izz="0.009864933638708275"
                    ixy="-1.5053124574783335e-05"
                    ixz="-0.0012144328835738973"
                    iyz="1.0434803501032979e-05" />
            </inertial>
        </xacro:if>
    </link>

    <link name="panda_link1">
        <visual name="panda_link1_visual">
            <geometry>
                <mesh filename="package://robot_description/meshes/visual/link1.dae" />
            </geometry>
        </visual>
        <collision name="panda_link1_collision">
            <geometry>
                <mesh filename="package://robot_description/meshes/collision/link1.stl" />
            </geometry>
        </collision>
        <xacro:if value="$(arg gazebo)">
            <inertial>
                <origin xyz="-3.72212e-09 -0.0324958 -0.0675818" rpy="0 0 0" />
                <mass value="2.6433170427227215" />
                <inertia
                    ixx="0.017405076982879724"
                    iyy="0.015352077935781732"
                    izz="0.005987891663073857"
                    ixy="-8.687986369621078e-09"
                    ixz="-1.6277819062920423e-08"
                    iyz="0.004510855959102245" />
            </inertial>
        </xacro:if>
    </link>

    <link name="panda_link2">
        <visual name="panda_link2_visual">
            <geometry>
                <mesh filename="package://robot_description/meshes/visual/link2.dae" />
            </geometry>
        </visual>
        <collision name="panda_link2_collision">
            <geometry>
                <mesh filename="package://robot_description/meshes/collision/link2.stl" />
            </geometry>
        </collision>
        <xacro:if value="$(arg gazebo)">
            <inertial>
                <origin xyz="3.17833e-07 -0.06861 0.0322285" rpy="0 0 0" />
                <mass value="2.6652755331661186" />
                <inertia
                    ixx="0.01778694005635383"
                    iyy="0.006044133867952844"
                    izz="0.01571095500455695"
                    ixy="8.70635625879119e-08"
                    ixz="3.752072058394008e-08"
                    iyz="-0.004599490295490376" />
            </inertial>
        </xacro:if>
    </link>

    <link name="panda_link3">
        <visual name="panda_link3_visual">
            <geometry>
                <mesh filename="package://robot_description/meshes/visual/link3.dae" />
            </geometry>
        </visual>
        <collision name="panda_link3_collision">
            <geometry>
                <mesh filename="package://robot_description/meshes/collision/link3.stl" />
            </geometry>
        </collision>
        <xacro:if value="$(arg gazebo)">
            <inertial>
                <origin xyz="0.0469893 0.0316374 -0.031704" rpy="0 0 0" />
                <mass value="2.3293714829045733" />
                <inertia
                    ixx="0.0075496764161139766"
                    iyy="0.009680676080191398"
                    izz="0.007944557422008086"
                    ixy="-0.0024320464513492225"
                    ixz="-0.003250815048103007"
                    iyz="-0.0021316282421730694" />
            </inertial>
        </xacro:if>
    </link>

    <link name="panda_link4">
        <visual name="panda_link4_visual">
            <geometry>
                <mesh filename="package://robot_description/meshes/visual/link4.dae" />
            </geometry>
        </visual>
        <collision name="panda_link4_collision">
            <geometry>
                <mesh filename="package://robot_description/meshes/collision/link4.stl" />
            </geometry>
        </collision>
        <xacro:if value="$(arg gazebo)">
            <inertial>
                <origin xyz="-0.0360505 0.0337069 0.0319019" rpy="0 0 0" />
                <mass value="2.3104763646281508" />
                <inertia
                    ixx="0.007764568814864828"
                    iyy="0.008015776929980149"
                    izz="0.009955882308071066"
                    ixy="0.003371475204045935"
                    ixz="-0.002343621113168248"
                    iyz="0.0022917526161470624" />
            </inertial>
        </xacro:if>
    </link>

    <link name="panda_link5">
        <visual name="panda_link5_visual">
            <geometry>
                <mesh filename="package://robot_description/meshes/visual/link5.dae" />
            </geometry>
        </visual>
        <collision name="panda_link5_collision">
            <geometry>
                <mesh filename="package://robot_description/meshes/collision/link5.stl" />
            </geometry>
        </collision>
        <xacro:if value="$(arg gazebo)">
            <inertial>
                <origin xyz="-6.12525e-06 0.0610427 -0.104176" rpy="0 0 0" />
                <mass value="2.6226426154892004" />
                <inertia
                    ixx="0.029070538014399377"
                    iyy="0.027638529986528795"
                    izz="0.004251111234400737"
                    ixy="6.208738268725568e-07"
                    ixz="-1.0059151925023392e-05"
                    iyz="-0.007424306477850814" />
            </inertial>
        </xacro:if>
    </link>

    <link name="panda_link6">
        <visual name="panda_link6_visual">
            <geometry>
                <mesh filename="package://robot_description/meshes/visual/link6.dae" />
            </geometry>
        </visual>
        <collision name="panda_link6_collision">
            <geometry>
                <mesh filename="package://robot_description/meshes/collision/link6.stl" />
            </geometry>
        </collision>
        <xacro:if value="$(arg gazebo)">
            <inertial>
                <origin value="0.051051 0.00910797 0.0106343" rpy="0 0 0" />
                <mass value="1.5025804886626795" />
                <inertia
                    ixx="0.002940555801469018"
                    iyy="0.00392105201248677"
                    izz="0.0054115603870960195"
                    ixy="-0.00042391108351381507"
                    ixz="0.000610007735338717"
                    iyz="0.00012647545430836214" />
            </inertial>
        </xacro:if>
    </link>

    <link name="panda_link7">
        <visual name="panda_link7_visual">
            <geometry>
                <mesh filename="package://robot_description/meshes/visual/link7.dae" />
            </geometry>
        </visual>
        <collision name="panda_link7_collision">
            <geometry>
                <mesh filename="package://robot_description/meshes/collision/link7.stl" />
            </geometry>
        </collision>
        <xacro:if value="$(arg gazebo)">
            <inertial>
                <origin xyz="0.0109695 0.0107965 0.0650412" rpy="0 0 0" />
                <mass value="0.5237668134788256" />
                <inertia
                    ixx="0.0008621467959726535"
                    iyy="0.0008613100184801048"
                    izz="0.0006961139396618219"
                    ixy="-0.00011871071570425467"
                    ixz="3.866602604509339e-05"
                    iyz="-9.057841649422724e-05" />
            </inertial>
        </xacro:if>
    </link>


    <!-- Arm Joints -->
    <joint name="panda_joint1" type="revolute">
        <origin xyz="0 0 0.333" rpy="0 0 0" />
        <parent link="panda_link0" />
        <child link="panda_link1" />
        <axis xyz="0 0 1" />
        <limit effort="87" lower="-2.897246558310587" upper="2.897246558310587" velocity="2.617993877991494" />
        <xacro:if value="$(arg gazebo)">
            <dynamics damping="21.75" friction="3.48" />
        </xacro:if>
    </joint>

    <joint name="panda_joint2" type="revolute">
        <origin xyz="0 0 0" rpy="-1.570796326794897 0 0" />
        <parent link="panda_link1" />
        <child link="panda_link2" />
        <axis xyz="0 0 1" />
        <limit effort="87" lower="-1.762782544514273" upper="1.762782544514273" velocity="2.617993877991494" />
        <xacro:if value="$(arg gazebo)">
            <dynamics damping="21.75" friction="3.48" />
        </xacro:if>
    </joint>

    <joint name="panda_joint3" type="revolute">
        <origin xyz="0 -0.316 0" rpy="1.570796326794897 0 0" />
        <parent link="panda_link2" />
        <child link="panda_link3" />
        <axis xyz="0 0 1" />
        <limit effort="87" lower="-2.897246558310587" upper="2.897246558310587" velocity="2.617993877991494" />
        <xacro:if value="$(arg gazebo)">
            <dynamics damping="21.75" friction="3.48" />
        </xacro:if>
    </joint>

    <joint name="panda_joint4" type="revolute">
        <origin xyz="0.0825 0 0" rpy="1.570796326794897 0 0" />
        <parent link="panda_link3" />
        <child link="panda_link4" />
        <axis xyz="0 0 1" />
        <limit effort="87" lower="-3.07177948351002" upper="-0.06981317007977318" velocity="2.617993877991494" />
        <xacro:if value="$(arg gazebo)">
            <dynamics damping="21.75" friction="3.48" />
        </xacro:if>
    </joint>

    <joint name="panda_joint5" type="revolute">
        <origin xyz="-0.0825 0.384 0" rpy="-1.570796326794897 0 0" />
        <parent link="panda_link4" />
        <child link="panda_link5" />
        <axis xyz="0 0 1" />
        <limit effort="12" lower="-2.897246558310587" upper="2.897246558310587" velocity="3.141592653589793" />
        <xacro:if value="$(arg gazebo)">
            <dynamics damping="3.0" friction="0.48" />
        </xacro:if>
    </joint>

    <joint name="panda_joint6" type="revolute">
        <origin xyz="0 0 0" rpy="1.570796326794897 0 0" />
        <parent link="panda_link5" />
        <child link="panda_link6" />
        <axis xyz="0 0 1" />
        <limit effort="12" lower="-0.0174532925199433" upper="3.752457891787809" velocity="3.141592653589793" />
        <xacro:if value="$(arg gazebo)">
            <dynamics damping="3.0" friction="0.48" />
        </xacro:if>
    </joint>

    <joint name="panda_joint7" type="revolute">
        <origin xyz="0.088 0 0" rpy="1.570796326794897 0 0" />
        <parent link="panda_link6" />
        <child link="panda_link7" />
        <axis xyz="0 0 1" />
        <limit effort="12" lower="-2.897246558310587" upper="2.897246558310587" velocity="3.141592653589793" />
        <xacro:if value="$(arg gazebo)">
            <dynamics damping="3.0" friction="0.48" />
        </xacro:if>
    </joint>
    
    <!-- Gazebo property -->
    <xacro:if value="$(arg gazebo)">
        <gazebo reference="panda_link0">
            <mu1>1.05</mu1>
            <mu2>1.05</mu2>
            <material>Gazebo/DarkGrey</material>
        </gazebo>

        <gazebo reference="panda_link1">
            <mu1>1.05</mu1>
            <mu2>1.05</mu2>
            <material>Gazebo/Orange</material>
        </gazebo>

        <gazebo reference="panda_link2">
            <mu1>1.05</mu1>
            <mu2>1.05</mu2>
            <material>Gazebo/Orange</material>
        </gazebo>

        <gazebo reference="panda_link3">
            <mu1>1.05</mu1>
            <mu2>1.05</mu2>
            <material>Gazebo/Orange</material>
        </gazebo>

        <gazebo reference="panda_link4">
            <mu1>1.05</mu1>
            <mu2>1.05</mu2>
            <material>Gazebo/Orange</material>
        </gazebo>

        <gazebo reference="panda_link5">
            <mu1>1.05</mu1>
            <mu2>1.05</mu2>
            <material>Gazebo/Orange</material>
        </gazebo>

        <gazebo reference="panda_link6">
            <mu1>1.05</mu1>
            <mu2>1.05</mu2>
            <material>Gazebo/Orange</material>
        </gazebo>

        <gazebo reference="panda_link7">
            <mu1>1.05</mu1>
            <mu2>1.05</mu2>
            <material>Gazebo/Orange</material>
        </gazebo>
    </xacro:if>

</robot>